Workbook

Sheet Dev Tracker
F3: Sprint | G3: =Sprints!C6 -> 2
F4: Days Outstanding | G4: =_xlfn.DAYS(Sprints!E6,Sprints!D6) -> -46065
C6: Sprint | D6: Ticket ID | E6: Type | F6: Title | G6: Description | H6: Priority | I6: Created Date | J6: Status | K6: Dependency (Ticket ID) | L6: Assigned To | M6: End Date | N6: Inital Est. Hours
C9: =Sprints!$C$5 -> 1 | D9: ="TMA-" & TEXT(ROWS($A$2:A2)-1,"000") -> TMA-000 | E9: Task | F9: *Hide "Cook with Taist" option, "Contact Taist" option, AND Search field on Customer side | G9: Tech Ref | H9: High | I9: =Sprints!$D$5 -> 45959 | J9: STAGING | L9: Billy | M9: =IF(C9<>"",VLOOKUP(C9,Sprints!C:G,3,FALSE),"") -> 45999 | N9: 1
C10: =Sprints!$C$5 -> 1 | D10: ="TMA-" & TEXT(ROWS($A$2:A3)-1,"000") -> TMA-001 | E10: Task | F10: Twilio text notifications | G10: Tech Ref | H10: High | I10: =Sprints!$D$5 -> 45959 | J10: STAGING | L10: Billy | M10: =IF(C10<>"",VLOOKUP(C10,Sprints!C:G,3,FALSE),"") -> 45999 | N10: 5
C11: =Sprints!$C$5 -> 1 | D11: ="TMA-" & TEXT(ROWS($A$2:A4)-1,"000") -> TMA-002 | E11: Task | F11: Only require phone number + email when signing up as a customer | G11: Tech Ref | H11: High | I11: =Sprints!$D$5 -> 45959 | J11: STAGING | L11: Billy | M11: =IF(C11<>"",VLOOKUP(C11,Sprints!C:G,3,FALSE),"") -> 45999 | N11: 2
C12: =Sprints!$C$5 -> 1 | D12: ="TMA-" & TEXT(ROWS($A$2:A5)-1,"000") -> TMA-003 | E12: Task | F12: Cart icon at top of Customer screen | G12: Tech Ref | H12: High | I12: =Sprints!$D$5 -> 45959 | J12: STAGING | L12: Billy | M12: =IF(C12<>"",VLOOKUP(C12,Sprints!C:G,3,FALSE),"") -> 45999 | N12: 5
C13: =Sprints!$C$5 -> 1 | D13: ="TMA-" & TEXT(ROWS($A$2:A6)-1,"000") -> TMA-004 | E13: Task | F13: *Simple tutorial overhaul (pictures, make it look nicer, make sure chefs don't skip it) | G13: Tech Ref | H13: High | I13: =Sprints!$D$5 -> 45959 | J13: STAGING | L13: Billy | M13: =IF(C13<>"",VLOOKUP(C13,Sprints!C:G,3,FALSE),"") -> 45999 | N13: 5
C14: =Sprints!$C$5 -> 1 | D14: ="TMA-" & TEXT(ROWS($A$2:A7)-1,"000") -> TMA-005 | E14: Task | F14: *Overall styling overhaul | G14: Tech Ref | H14: High | I14: =Sprints!$D$5 -> 45959 | J14: In Progress | L14: Billy | M14: =IF(C14<>"",VLOOKUP(C14,Sprints!C:G,3,FALSE),"") -> 45999 | N14: 4
C15: =Sprints!$C$5 -> 1 | D15: ="TMA-" & TEXT(ROWS($A$2:A8)-1,"000") -> TMA-006 | E15: Task | F15: *Simplify chef stripe signup without moving to app | G15: Tech Ref | H15: High | I15: =Sprints!$D$5 -> 45959 | J15: STAGING | L15: Billy | M15: =IF(C15<>"",VLOOKUP(C15,Sprints!C:G,3,FALSE),"") -> 45999 | N15: 4
C16: =Sprints!$C$5 -> 1 | D16: ="TMA-" & TEXT(ROWS($A$2:A9)-1,"000") -> TMA-007 | E16: Task | F16: Coupon code functionality | G16: Tech Ref | H16: Medium | I16: =Sprints!$D$5 -> 45959 | J16: STAGING | L16: Billy | M16: =IF(C16<>"",VLOOKUP(C16,Sprints!C:G,3,FALSE),"") -> 45999 | N16: 8
C17: =Sprints!$C$5 -> 1 | D17: ="TMA-" & TEXT(ROWS($A$2:A10)-1,"000") -> TMA-008 | E17: Task | F17: **Overhaul entire chef signup flow (not 1 long form, prepopulate stuff if available, address auto finish) | G17: Tech Ref | H17: High | I17: =Sprints!$D$5 -> 45959 | J17: STAGING | L17: Billy | M17: =IF(C17<>"",VLOOKUP(C17,Sprints!C:G,3,FALSE),"") -> 45999 | N17: 8
C18: =Sprints!$C$5 -> 1 | D18: ="TMA-" & TEXT(ROWS($A$2:A11)-1,"000") -> TMA-009 | E18: Task | F18: *AI for menu page | G18: Tech Ref | H18: High | I18: =Sprints!$D$5 -> 45959 | J18: STAGING | L18: Billy | M18: =IF(C18<>"",VLOOKUP(C18,Sprints!C:G,3,FALSE),"") -> 45999 | N18: 8
C19: =Sprints!$C$5 -> 1 | D19: ="TMA-" & TEXT(ROWS($A$2:A12)-1,"000") -> TMA-010 | E19: Task | F19: Move from AWS to Railway | G19: Tech Ref | H19: Medium | I19: =Sprints!$D$5 -> 45959 | J19: STAGING | L19: Billy | M19: =IF(C19<>"",VLOOKUP(C19,Sprints!C:G,3,FALSE),"") -> 45999 | N19: 8
C20: =Sprints!$C$5 -> 1 | D20: ="TMA-" & TEXT(ROWS($A$2:A13)-1,"000") -> TMA-011 | E20: Task | F20: **Calendar overhaul | G20: Tech Ref | H20: High | I20: =Sprints!$D$5 -> 45959 | J20: STAGING | L20: Billy | M20: =IF(C20<>"",VLOOKUP(C20,Sprints!C:G,3,FALSE),"") -> 45999 | N20: 8
... C30: =Sprints!$C$5 -> 1 | D30: ="TMA-" & TEXT(ROWS($A$2:A23)-1,"000") -> TMA-021 | E30: Bug | F30: From Order Date selection, ONLY able to tap back button to return to the current day, if user has the exact DAY OF WEEK selected as is the current day (e.g., today is Wednesday; if looking at next week, user can only tap back button when on Wed, not Tue) | G30: Tech Ref | H30: Medium | I30: =Sprints!$D$5 -> 45959 | J30: STAGING | L30: Billy | M30: =IF(C30<>"",VLOOKUP(C30,Sprints!C:G,3,FALSE),"") -> 45999 | N30: 0.5
C31: 1.5 | D31: ="TMA-" & TEXT(ROWS($A$2:A58)-1,"000") -> TMA-056 | E31: Task | F31: UTC time zone for customer seeing chef availability (ordering for tomorrow) | H31: High | I31: 45665 | L31: Billy
C32: 1.5 | D32: ="TMA-" & TEXT(ROWS($A$2:A59)-1,"000") -> TMA-057 | E32: Bug | F32: Words being cut off on the end (last letter) on Android | H32: High | I32: 45665 | J32: STAGING | L32: Billy
C33: 1.5 | D33: ="TMA-" & TEXT(ROWS($A$2:A60)-1,"000") -> TMA-058 | E33: Task | F33: On my Way' and 'Order Complete' notification verbiage | H33: High | I33: 45665 | J33: STAGING | L33: Billy
C34: 1.5 | D34: ="TMA-" & TEXT(ROWS($A$2:A61)-1,"000") -> TMA-059 | E34: Task | F34: Add Menu Item Image | H34: Medium | I34: 45665 | J34: STAGING | L34: Billy
C35: 1.5 | D35: ="TMA-" & TEXT(ROWS($A$2:A62)-1,"000") -> TMA-060 | E35: Bug | F35: Android keyboard blocks special instructions textbox. Keyboard also blocks chat screen between customer and chef | H35: Medium | I35: 45666 | L35: Billy
C36: 1.5 | D36: ="TMA-" & TEXT(ROWS($A$2:A64)-1,"000") -> TMA-062 | E36: Bug | F36: Order request text message to chef is missing first name of customer | H36: High | I36: 45666 | L36: Billy
C37: 1.5 | D37: ="TMA-" & TEXT(ROWS($A$2:A31)-1,"000") -> TMA-029 | E37: Bug | F37: Android Tip/Review screen verbiage checks | H37: High | I37: 45666 | L37: Billy
C38: =Sprints!$C$6 -> 2 | D38: ="TMA-" & TEXT(ROWS($A$2:A65)-1,"000") -> TMA-063 | E38: Task | F38: Regular reminder notifications to order (2pm ish on random weekdays) | H38: High | I38: 46058
C39: =Sprints!$C$6 -> 2 | D39: ="TMA-" & TEXT(ROWS($A$2:A24)-1,"000") -> TMA-022 | E39: Bug | F39: Profile (bio and hours) not visible from Admin Panel pre activation | G39: Pre-activation | H39: Medium | I39: 45972
C40: =Sprints!$C$6 -> 2 | D40: ="TMA-" & TEXT(ROWS($A$2:A25)-1,"000") -> TMA-023 | E40: Task | F40: Remove Serving Size and replace with MOQ (every item serves 1 person to start); except for meal prep items | H40: Low | I40: 45974 | K40: TMA-034
C41: =Sprints!$C$6 -> 2 | D41: ="TMA-" & TEXT(ROWS($A$2:A26)-1,"000") -> TMA-024 | E41: Task | F41: Automatic app updates for users | H41: Low | I41: 45974
C42: =Sprints!$C$6 -> 2 | D42: ="TMA-" & TEXT(ROWS($A$2:A27)-1,"000") -> TMA-025 | E42: Task | F42: Add Stripe Transaction notifications | G42: https://dashboard.stripe.com/acct_1KWXqKKujvfsOOCM/workbench/webhooks | H42: Medium | I42: 45983
C43: =Sprints!$C$6 -> 2 | D43: ="TMA-" & TEXT(ROWS($A$2:A28)-1,"000") -> TMA-026 | E43: Task | F43: Email Campaign Automation | G43: Look into Make.com | H43: High | I43: 45992
C44: =Sprints!$C$6 -> 2 | D44: ="TMA-" & TEXT(ROWS($A$2:A29)-1,"000") -> TMA-027 | E44: Task | F44: Switch Review character account from 100 to 200 | H44: Medium | I44: 45993
C45: =Sprints!$C$6 -> 2 | D45: ="TMA-" & TEXT(ROWS($A$2:A30)-1,"000") -> TMA-028 | E45: Task | F45: Assure all time values in Admin Panel are set to EST (or EDT) | H45: Low | I45: 45994
C46: =Sprints!$C$6 -> 2 | D46: ="TMA-" & TEXT(ROWS($A$2:A39)-1,"000") -> TMA-037 | E46: Task | F46: Add time blockout logic for before, during, and after already-accepted orders | H46: High | I46: 45995
C47: =Sprints!$C$6 -> 2 | D47: ="TMA-" & TEXT(ROWS($A$2:A40)-1,"000") -> TMA-038 | E47: Task | F47: Replace onboarding graphics with masks for ones without masks | H47: Low | I47: 45995
C48: =Sprints!$C$6 -> 2 | D48: ="TMA-" & TEXT(ROWS($A$2:A41)-1,"000") -> TMA-039 | E48: Task | F48: Chef button to notify customer of arrival; "Your chef has arrived." | H48: Low | I48: 46000
C49: =Sprints!$C$6 -> 2 | D49: ="TMA-" & TEXT(ROWS($A$2:A42)-1,"000") -> TMA-040 | E49: Task | F49: Reminder to Chef to put bag/cooler on floor and wash hands | H49: Medium | I49: 46000
C50: =Sprints!$C$6 -> 2 | D50: ="TMA-" & TEXT(ROWS($A$2:A43)-1,"000") -> TMA-041 | E50: Task | F50: Create Menu Item flow to start with "Standard? Ideal for customers wanting a dish for that evening" or "Meal Prep? Ideal for customers wanting to reheat over a week" | H50: Medium | I50: 46000
C51: =Sprints!$C$6 -> 2 | D51: ="TMA-" & TEXT(ROWS($A$2:A44)-1,"000") -> TMA-042 | E51: Task | F51: Chef messaging to avoid frozen ingredients (proteins) when creating menu items | H51: Medium | I51: 46000
C52: =Sprints!$C$6 -> 2 | D52: ="TMA-" & TEXT(ROWS($A$2:A45)-1,"000") -> TMA-043 | E52: Task | F52: Reminder to Chef to turn off any appliances and wipe down surfaces at the time of the order completion (based on arrival time and completion time) | H52: Medium | I52: 46000
C53: =Sprints!$C$6 -> 2 | D53: ="TMA-" & TEXT(ROWS($A$2:A46)-1,"000") -> TMA-044 | E53: Task | F53: Reminder to Chef that order should almost be complete | G53: when order is 10 minutes to completion (based on arrival time and completion time) | H53: Low | I53: 46000
C54: =Sprints!$C$6 -> 2 | D54: ="TMA-" & TEXT(ROWS($A$2:A47)-1,"000") -> TMA-045 | E54: Task | F54: Alternate time selection field layouts for Android | H54: Low | I54: 46000
...

Sheet Comments & Pics
C2: Ticket ID | D2: Comment or Picture | E2: Author | F2: Date
C3: ='Dev Tracker'!D18 -> TMA-009 | D3: Example 1: Grilled lemon-garlic chicken (or tofu), turmeric quinoa, roasted rainbow veggies, avocado fan, tahini-lime drizzle, and microgreens Example 2: Chickpea pasta in roasted red pepper cashew cream, sautéed spinach, blistered cherry tomatoes, tomato basil chicken sausage, and garlic herb sourdough Example 3: • Day 1: Blackened salmon, wild rice, grilled asparagus • Day 2: Bison meatballs, sweet potato mash, sautéed kale • Day 3: Sauteed Korean BBQ chicken thighs, broccoli, and jasmine rice | E3: Dayne | F3: 45973
C4: ='Dev Tracker'!D39 -> TMA-022 | D4: CAN see Profile on Admin Panel upon activating the chef | E4: Dayne | F4: 45974
C5: ='Dev Tracker'!D14 -> TMA-005 | D5: Assuring size of text and objects is proportional to device screen Assuring white "flash" box is removed when loading into app | E5: Dayne | F5: 45974
C6: ='Dev Tracker'!D39 -> TMA-022 | D6: https://teamtaist.sharepoint.com/:i:/s/Taist2/IQClpkwtP2YYQaj_rRyCZUFNAbqJhhrWTbYYABngX6kSNUU?e=YicLpL | E6: Dayne | F6: 45974
C7: ='Dev Tracker'!D39 -> TMA-022 | D7: https://teamtaist.sharepoint.com/:i:/s/Taist2/IQDfYV_GLez0QZhNZiFb8w7HAcFgLkVSXghvKsfuaA0ceMc?e=KOGDCM | E7: Dayne | F7: 45974
C8: =C5 -> TMA-005 | D8: Centering logo and signup/login buttons on Welcome Page Eliminating white-on-white logos
C9: ='Dev Tracker'!D43 -> TMA-026 | D9: Using Resend for transactional emails Need to look into marketing (time-based) emails towards customers and chefs | E9: Dayne | F9: 46000
C10: ='Dev Tracker'!D17 -> TMA-008 | D10: Can chef be taken back to Home tab after creating first menu item? | E10: Dayne | F10: 46000
C11: ='Dev Tracker'!D15 -> TMA-006 | D11: Can chef be shown the Home tab (instead of inside Step 4), if not taken directly back to Home tab automatically after completing stripe account | E11: Dayne | F11: 46000

Sheet Deprioritized
C2: Sprint | D2: Ticket ID | E2: Type | F2: Title | G2: Description | H2: Priority | I2: Created Date | J2: Status | K2: Dependency (Ticket ID) | L2: Assigned To | M2: End Date | N2: Initial Est. Hours

Sheet Sprints
C3: Sprint # | D3: Start Date | E3: End Date | F3: End Date (Actual) | G3: Total Hours
C5: 1 | D5: 45959 | E5: 45999 | F5: 46055 | G5: 81
C6: 2 | D6: 46065

Sheet Users
A1: Initials | B1: Name
A2: AA | B2: Dayne
A3: DA | B3: Daryl
A4: BG | B4: Billy
A5: S1 | B5: Sprint 1
